Workbook
Name CASE: 'LBO - YM Final'!$E$7
Name CASE: #REF!
Name CIRC: 'LBO - YM Final'!$E$6
Name CIRC: #REF!
Name PIK: 'LBO - YM Final'!$E$8:$E$8
Name PIK: #REF!

Sheet Cover
B2: Cover
A4: x | B4: Creating the Burger King LBO Model Processes
B5: - Assumptions Provided | G5: - Forecasting Cash Flow Statement
B6: - Sources and Uses Table | G6: - Forecasting Balance Sheet
B7: - Building the Operating Model | G7: - USD & EUR Debt Tranches (e.g. revolver)
B8: - Building the Debt Schedule | G8: - Mandatory Debt Repayments
B9: - IRR Calculations | G9: - PIK
B10: - Obtain Assumptions Based on Real Tax Figures | G10: - Cash Sweep
B11: - Sources and Uses Table | G11: - LIBOR
B12: - Operating Model With Two Scenarios | G12: - Amortization of Financing Fees
B13: - Debt Schedule With Circuit Breaker | G13: - Sensitivity Table
B14: - Revenue Cases | G14: - Adding a DCF

Sheet LBO - YM Final
B2: LBO
A4: x | B4: Switches
B6: Circuit Breaker | E6: OFF | I6: IRR (for reference) | K6: =K308 -> 0.2124125
B7: Case | E7: 2 | F7: =IF(E7=1,"Conservative","Management") -> Management | I7: Revolver Check | K7: =G218 -> OK
B8: PIK Toggle | E8: 1 | F8: =IF(E8=1,"Cash","PIK") -> Cash
A10: x | B10: Assumptions
B12: Transaction Background | H12: Valuation at Entry
B13: Company name | E13: Burger King | H13: Offer value / share | K13: 24
B14: Ticker | E14: BKC | H14: % Premium / Discount | K14: =K13/E15-1 -> 0.27253446
B15: Latest closing share price | E15: 18.86
B16: Latest closing share price date | E16: 40422 | H16: Offer value (Equity value) | K16: =K13*K17 -> 3325.4354
H17: Diluted Shares Outstanding | K17: ='Shares - YM'!E16 -> 138.55981
B19: Transaction Financials and Assumptions | H19: Debt | K19: =E21 -> 755.4
B20: LTM EBITDA | E20: =F100 -> 444.6 | H20: Cash | K20: =E22 -> 187.6
B21: Debt | E21: =93.3+667.7-5.6 -> 755.4
B22: Cash | E22: =187.6 -> 187.6 | H22: Enterprise Value | K22: =K16+K19-K20 -> 3893.2354
B23: Minimum Cash | E23: =E22-69.4 -> 118.2 | H23: LTM EBITDA | K23: =E20 -> 444.6
B24: Exit Multiple | E24: =K24 -> 8.7567148 | H24: Entry Multiple | K24: =K22/K23 -> 8.7567148
B26: Capital Structure
E27: Amount | F27: xEBITDA | G27: Interest (%) | H27: Fees (%) | I27: Fee ($) | J27: Term | K27: Amortization
B28: Revolver | E28: 0 | F28: =E28/E$20 -> 0 | G28: 0.045 | H28: 0 | I28: =E28*H28 -> 0 | J28: 5 | K28: =I28/J28 -> 0
B29: Secured Term Loan - USD Tranche | E29: 1510 | F29: =E29/E$20 -> 3.3963113 | G29: 0.0682 | H29: 0.027 | I29: =E29*H29 -> 40.77 | J29: 6 | K29: =I29/J29 -> 6.795
B30: Secured Term Loan - EUR Tranche | E30: 334.2 | F30: =E30/E$20 -> 0.75168691 | G30: 0.0711 | H30: 0.0251 | I30: =E30*H30 -> 8.38842 | J30: 6 | K30: =I30/J30 -> 1.39807
B31: Senior Notes | E31: 800 | F31: =E31/E$20 -> 1.7993702 | G31: 0.1019 | H31: 0.0251 | I31: =E31*H31 -> 20.08 | J31: 8 | K31: =I31/J31 -> 2.51 | L31: PIK
B32: Subordinated Notes | E32: 0 | F32: =E32/E$20 -> 0 | G32: 0.1 | H32: 0 | I32: =E32*H32 -> 0 | J32: 5 | K32: =I32/J32 -> 0 | L32: 0.05
B33: Preferred Equity | E33: 0 | F33: =E33/E$20 -> 0 | G33: 0.1 | H33: 0 | I33: =E33*H33 -> 0 | J33: 5 | K33: =I33/J33 -> 0
B35: Total | E35: =SUM(E28:E33) -> 2644.2 | F35: =SUM(F28:F33) -> 5.9473684 | I35: =SUM(I28:I33) -> 69.23842 | K35: =SUM(K28:K33) -> 10.70307
A37: x | B37: Sources and Uses
B39: Sources | H39: Uses
D40: Amount | E40: xEBITDA | F40: % Capital | I40: Amount | J40: xEBITDA | K40: % Capital
B41: =B28 -> Revolver | D41: =E28 -> 0 | E41: =D41/$E$20 -> 0 | F41: =D41/$D$50 -> 0 | H41: Equity Payment | I41: =K16 -> 3325.4354 | J41: =I41/$E$20 -> 7.4796118 | K41: =I41/$D$50 -> 0.77813446
B42: =B29 -> Secured Term Loan - USD Tranche | D42: =E29 -> 1510 | E42: =D42/$E$20 -> 3.3963113 | F42: =D42/$D$50 -> 0.35333209 | H42: Debt Refinanciang | I42: =E21 -> 755.4 | J42: =I42/$E$20 -> 1.6990553 | K42: =I42/$D$50 -> 0.17675964
B43: =B30 -> Secured Term Loan - EUR Tranche | D43: =E30 -> 334.2 | E43: =D43/$E$20 -> 0.75168691 | F43: =D43/$D$50 -> 0.078201048 | H43: Transaction Fees | I43: 91.2 | J43: =I43/$E$20 -> 0.20512821 | K43: =I43/$D$50 -> 0.021340322
B44: =B31 -> Senior Notes | D44: =E31 -> 800 | E44: =D44/$E$20 -> 1.7993702 | F44: =D44/$D$50 -> 0.18719581 | H44: Financiang Fees | I44: =I35 -> 69.23842 | J44: =I44/$E$20 -> 0.15573194 | K44: =I44/$D$50 -> 0.016201427
B45: =B32 -> Subordinated Notes | D45: 0 | E45: =D45/$E$20 -> 0 | F45: =D45/$D$50 -> 0
B46: =B33 -> Preferred Equity | D46: 0 | E46: =D46/$E$20 -> 0 | F46: =D46/$D$50 -> 0 | H46: Other | I46: 32.326172 | J46: =I46/$E$20 -> 0.072708439 | K46: =I46/$D$50 -> 0.0075641548
B47: Cash on hand | D47: =E22-E23 -> 69.4 | E47: =D47/$E$20 -> 0.15609537 | F47: =D47/$D$50 -> 0.016239236
B48: Sponsor Equity | D48: =D50-SUM(D41:D47) -> 1560 | E48: =D48/$E$20 -> 3.5087719 | F48: =D48/$D$50 -> 0.36503182
B50: Total | D50: =I50 -> 4273.6 | E50: =SUM(E41:E48) -> 9.6122357 | F50: =SUM(F42:F48) -> 1 | H50: Total | I50: =SUM(I41:I47) -> 4273.6 | J50: =SUM(J41:J47) -> 9.6122357 | K50: =SUM(K41:K47) -> 1
A52: x | B52: Financials (6/30 FYE)
...

Sheet DCF - YM
B2: DCF
B4: WACC | D4: 0.1
B5: TGR | D5: 0.025
F6: 1 | G6: 2 | H6: 3 | I6: 4 | J6: 5 | L6: Year - Discount Period
B7: DCF (6/30, USD M) | E7: 2010A | F7: 2011E | G7: 2012E | H7: 2013E | I7: 2014E | J7: 2015E
B8: Revenue | E8: ='LBO - YM Final'!F63 -> 2502.2 | F8: ='LBO - YM Final'!G63 -> 2574 | G8: ='LBO - YM Final'!H63 -> 2102 | H8: ='LBO - YM Final'!I63 -> 1884 | I8: ='LBO - YM Final'!J63 -> 1910 | J8: ='LBO - YM Final'!K63 -> 2024
B9: % growth | F9: =F8/E8-1 -> 0.028694749 | G9: =G8/F8-1 -> -0.18337218 | H9: =H8/G8-1 -> -0.10371075 | I9: =I8/H8-1 -> 0.013800425 | J9: =J8/I8-1 -> 0.059685864
B11: EBIT | E11: ='LBO - YM Final'!F75 -> 332.9 | F11: ='LBO - YM Final'!G75 -> 351 | G11: ='LBO - YM Final'!H75 -> 426 | H11: ='LBO - YM Final'!I75 -> 465 | I11: ='LBO - YM Final'!J75 -> 528 | J11: ='LBO - YM Final'!K75 -> 589
B12: % of sales | F12: =E11/F8 -> 0.12933178 | G12: =F11/G8 -> 0.16698382 | H12: =G11/H8 -> 0.22611465 | I12: =H11/I8 -> 0.2434555 | J12: =I11/J8 -> 0.26086957
B14: Taxes | E14: =E11*E15 -> 114.16725 | F14: =F11*F15 -> 118.6196 | G14: =G11*G15 -> 141.83567 | H14: =H11*H15 -> 152.49563 | I14: =I11*I15 -> 170.51633 | J14: =J11*J15 -> 187.27113
B15: Tax rate | E15: ='LBO - YM Final'!F91 -> 0.34294759 | F15: ='LBO - YM Final'!G91 -> 0.33794759 | G15: ='LBO - YM Final'!H91 -> 0.33294759 | H15: ='LBO - YM Final'!I91 -> 0.32794759 | I15: ='LBO - YM Final'!J91 -> 0.32294759 | J15: ='LBO - YM Final'!K91 -> 0.31794759
B17: EBIAT | F17: =F11-F14 -> 232.3804 | G17: =G11-G14 -> 284.16433 | H17: =H11-H14 -> 312.50437 | I17: =I11-I14 -> 357.48367 | J17: =J11-J14 -> 401.72887
B19: D&A | F19: ='LBO - YM Final'!G166 -> 113 | G19: ='LBO - YM Final'!H166 -> 92 | H19: ='LBO - YM Final'!I166 -> 98 | I19: ='LBO - YM Final'!J166 -> 92 | J19: ='LBO - YM Final'!K166 -> 96
B20: % of sales | F20: =F19/F8 -> 0.043900544 | G20: =G19/G8 -> 0.04376784 | H20: =H19/H8 -> 0.052016985 | I20: =I19/I8 -> 0.048167539 | J20: =J19/J8 -> 0.04743083
B22: CapEx | F22: ='LBO - YM Final'!G137 -> 182.80533 | G22: ='LBO - YM Final'!H137 -> 149.28392 | H22: ='LBO - YM Final'!I137 -> 133.80157 | I22: ='LBO - YM Final'!J137 -> 135.64809 | J22: ='LBO - YM Final'!K137 -> 143.74436
B23: % of sales | F23: =F22/F8 -> 0.071019942 | G23: =G22/G8 -> 0.071019942 | H23: =H22/H8 -> 0.071019942 | I23: =I22/I8 -> 0.071019942 | J23: =J22/J8 -> 0.071019942
B25: Change in NWC | F25: ='LBO - YM Final'!G132 -> -6.0540962 | G25: ='LBO - YM Final'!H132 -> 25.553665 | H25: ='LBO - YM Final'!I132 -> 11.802328 | I25: ='LBO - YM Final'!J132 -> -1.4076171 | J25: ='LBO - YM Final'!K132 -> -6.1718597
B26: % of sales | F26: =F25/F8 -> -0.0023520187 | G26: =G25/G8 -> 0.012156834 | H26: =H25/H8 -> 0.0062645055 | I26: =I25/I8 -> -0.00073697232 | J26: =J25/J8 -> -0.0030493378
B28: Unlevered FCF | F28: =F17+F19-F22-F25 -> 168.62916 | G28: =G17+G19-G22-G25 -> 201.32674 | H28: =H17+H19-H22-H25 -> 264.90047 | I28: =I17+I19-I22-I25 -> 315.2432 | J28: =J17+J19-J22-J25 -> 360.15637
B29: PV of Unlevered FCF | F29: =F28/(1+$D$4)^F6 -> 153.29924 | G29: =G28/(1+$D$4)^G6 -> 166.38574 | H29: =H28/(1+$D$4)^H6 -> 199.02364 | I29: =I28/(1+$D$4)^I6 -> 215.31535 | J29: =J28/(1+$D$4)^J6 -> 223.62877
B31: Terminal Value | J31: =(J28*(1+D5))/(D4-D5) -> 4922.137
B32: PV of Terminal Value | J32: =J31/(1+D4)^J6 -> 3056.2598
B34: Enterprise Value | J34: =SUM(F29:J29,J32) -> 4013.9125
B35: Cash | J35: ='LBO - YM Final'!E22 -> 187.6
B36: Debt | J36: ='LBO - YM Final'!E21 -> 755.4
B37: Equity Value | J37: =J34+J35-J36 -> 3446.1125
B39: FDSO | J39: ='LBO - YM Final'!K17 -> 138.55981
B40: Share Price | J40: ='DCF - YM'!J37/'DCF - YM'!J39 -> 24.870939
B41: Offer Price (For Reference) | J41: ='LBO - YM Final'!K13 -> 24
B42: Discount / (Premium) | J42: =J41/J40-1 -> -0.03501834

Sheet WACC - YM
B2: WACC
B4: WACC = % of equity x cost of equity + % of debt x cost of debt x (1 - Tax Rate)
B5: Cost of equity = Risk free rate + Beta x Market Risk Premium
A7: x | B7: WACC
B8: Market Cap | F8: ='LBO - YM Final'!E15*'LBO - YM Final'!K17 -> 2613.238
B9: % of Equity
B10: Cost of Equity
B11: Risk Free Rate | F11: 0.0272 | G11: 10Y TREASURY YIELD ON 9/1/2010
B12: Beta | G12: HISTORICAL BETA ON 9/1/2010
B13: Market Risk Premium
B15: Debt
B16: % of Debt
B17: Cost of Debt
B18: Tax Rate
B20: Total
A22: x | B22: WACC

Sheet Shares - YM
B2: Diluted Share Count Calculation
A4: x | B4: Full Diluted Shares
B6: Offer price | E6: ='LBO - YM Final'!K13 -> 24
B7: Basic shares outstanding (latest filing) | E7: 136.55564
B8: In-the-money exercisable options | E8: =E32 -> 7.4212
B9: Total proceeds ($mm) | E9: =SUMPRODUCT(D21:D31,E21:E31) -> 129.35152
B10: Total shares repurchased (mm) | E10: =E9/E6 -> 5.3896465
B11: Net dilutive options | E11: =E8-E10 -> 2.0315535
B12: Dilutive impact of shares from other securities | E12: 1.7296
B14: Settled stock based comp | E14: =48.1/E6 -> 2.0041667
B16: Net diluted shares outstanding | E16: =E7+E14 -> 138.55981
A18: x | B18: Options outstanding
C20: Outstanding | D20: Exercise price | E20: Dilutive Shares
B21: 1 | C21: 7.4212 | D21: 17.43 | E21: =IF(D21<$E$6,C21) -> 7.4212
B22: =B21+1 -> 2 | E22: =IF(D22<$E$6,C22) -> 0
B24: =B22+1 -> 3 | E24: =IF(D24<$E$6,C24) -> 0
B25: =B24+1 -> 4 | E25: =IF(D25<$E$6,C25) -> 0
B26: =B25+1 -> 5 | E26: =IF(D26<$E$6,C26) -> 0
B27: =B26+1 -> 6 | E27: =IF(D27<$E$6,C27) -> 0
B28: =B27+1 -> 7 | E28: =IF(D28<$E$6,C28) -> 0
B29: =B28+1 -> 8 | E29: =IF(D29<$E$6,C29) -> 0
B30: =B29+1 -> 9 | E30: =IF(D30<$E$6,C30) -> 0
B31: =B30+1 -> 10 | E31: =IF(D31<$E$6,C31) -> 0
A32: x | B32: Total | E32: =SUM(E21:E31) -> 7.4212
